{
 "cells": [
  {
   "cell_type": "code",
   "execution_count": null,
   "metadata": {},
   "outputs": [
    {
     "name": "stderr",
     "output_type": "stream",
     "text": [
      "ERROR:root:Internal Python error in the inspect module.\n",
      "Below is the traceback from this internal error.\n",
      "\n",
      "ERROR:root:Internal Python error in the inspect module.\n",
      "Below is the traceback from this internal error.\n",
      "\n",
      "ERROR:root:Internal Python error in the inspect module.\n",
      "Below is the traceback from this internal error.\n",
      "\n"
     ]
    },
    {
     "name": "stdout",
     "output_type": "stream",
     "text": [
      "Traceback (most recent call last):\n",
      "  File \"C:\\Users\\momad\\AppData\\Roaming\\Python\\Python36\\site-packages\\IPython\\core\\interactiveshell.py\", line 3343, in run_code\n",
      "    exec(code_obj, self.user_global_ns, self.user_ns)\n",
      "  File \"<ipython-input-2-1458a38dfacc>\", line 35, in <module>\n",
      "    model = design_model(features_train)\n",
      "  File \"<ipython-input-2-1458a38dfacc>\", line 18, in design_model\n",
      "    model.add(Dense(1))\n",
      "NameError: name 'Dense' is not defined\n",
      "\n",
      "During handling of the above exception, another exception occurred:\n",
      "\n",
      "Traceback (most recent call last):\n",
      "  File \"C:\\Users\\momad\\AppData\\Roaming\\Python\\Python36\\site-packages\\IPython\\core\\interactiveshell.py\", line 2044, in showtraceback\n",
      "    stb = value._render_traceback_()\n",
      "AttributeError: 'NameError' object has no attribute '_render_traceback_'\n",
      "\n",
      "During handling of the above exception, another exception occurred:\n",
      "\n",
      "Traceback (most recent call last):\n",
      "  File \"C:\\Users\\momad\\AppData\\Roaming\\Python\\Python36\\site-packages\\IPython\\core\\ultratb.py\", line 1169, in get_records\n",
      "    return _fixed_getinnerframes(etb, number_of_lines_of_context, tb_offset)\n",
      "  File \"C:\\Users\\momad\\AppData\\Roaming\\Python\\Python36\\site-packages\\IPython\\core\\ultratb.py\", line 316, in wrapped\n",
      "    return f(*args, **kwargs)\n",
      "  File \"C:\\Users\\momad\\AppData\\Roaming\\Python\\Python36\\site-packages\\IPython\\core\\ultratb.py\", line 350, in _fixed_getinnerframes\n",
      "    records = fix_frame_records_filenames(inspect.getinnerframes(etb, context))\n",
      "  File \"C:\\Users\\momad\\anaconda3\\envs\\PythonData\\lib\\inspect.py\", line 1490, in getinnerframes\n",
      "    frameinfo = (tb.tb_frame,) + getframeinfo(tb, context)\n",
      "  File \"C:\\Users\\momad\\anaconda3\\envs\\PythonData\\lib\\inspect.py\", line 1448, in getframeinfo\n",
      "    filename = getsourcefile(frame) or getfile(frame)\n",
      "  File \"C:\\Users\\momad\\anaconda3\\envs\\PythonData\\lib\\inspect.py\", line 696, in getsourcefile\n",
      "    if getattr(getmodule(object, filename), '__loader__', None) is not None:\n",
      "  File \"C:\\Users\\momad\\anaconda3\\envs\\PythonData\\lib\\inspect.py\", line 733, in getmodule\n",
      "    if ismodule(module) and hasattr(module, '__file__'):\n",
      "  File \"C:\\Users\\momad\\anaconda3\\envs\\PythonData\\lib\\site-packages\\tensorflow\\__init__.py\", line 50, in __getattr__\n",
      "    module = self._load()\n",
      "  File \"C:\\Users\\momad\\anaconda3\\envs\\PythonData\\lib\\site-packages\\tensorflow\\__init__.py\", line 44, in _load\n",
      "    module = _importlib.import_module(self.__name__)\n",
      "  File \"C:\\Users\\momad\\anaconda3\\envs\\PythonData\\lib\\importlib\\__init__.py\", line 126, in import_module\n",
      "    return _bootstrap._gcd_import(name[level:], package, level)\n",
      "  File \"<frozen importlib._bootstrap>\", line 994, in _gcd_import\n",
      "  File \"<frozen importlib._bootstrap>\", line 971, in _find_and_load\n",
      "  File \"<frozen importlib._bootstrap>\", line 955, in _find_and_load_unlocked\n",
      "  File \"<frozen importlib._bootstrap>\", line 665, in _load_unlocked\n",
      "  File \"<frozen importlib._bootstrap_external>\", line 678, in exec_module\n",
      "  File \"<frozen importlib._bootstrap>\", line 219, in _call_with_frames_removed\n",
      "  File \"C:\\Users\\momad\\anaconda3\\envs\\PythonData\\lib\\site-packages\\tensorflow_core\\contrib\\__init__.py\", line 39, in <module>\n",
      "    from tensorflow.contrib import compiler\n",
      "  File \"C:\\Users\\momad\\anaconda3\\envs\\PythonData\\lib\\site-packages\\tensorflow_core\\contrib\\compiler\\__init__.py\", line 21, in <module>\n",
      "    from tensorflow.contrib.compiler import jit\n",
      "  File \"C:\\Users\\momad\\anaconda3\\envs\\PythonData\\lib\\site-packages\\tensorflow_core\\contrib\\compiler\\__init__.py\", line 22, in <module>\n",
      "    from tensorflow.contrib.compiler import xla\n",
      "  File \"C:\\Users\\momad\\anaconda3\\envs\\PythonData\\lib\\site-packages\\tensorflow_core\\contrib\\compiler\\xla.py\", line 22, in <module>\n",
      "    from tensorflow.python.estimator import model_fn as model_fn_lib\n",
      "  File \"C:\\Users\\momad\\anaconda3\\envs\\PythonData\\lib\\site-packages\\tensorflow_core\\python\\estimator\\model_fn.py\", line 26, in <module>\n",
      "    from tensorflow_estimator.python.estimator import model_fn\n",
      "  File \"C:\\Users\\momad\\anaconda3\\envs\\PythonData\\lib\\site-packages\\tensorflow_estimator\\python\\estimator\\model_fn.py\", line 29, in <module>\n",
      "    from tensorflow.python.types import core\n",
      "ModuleNotFoundError: No module named 'tensorflow.python.types'\n",
      "Traceback (most recent call last):\n",
      "  File \"C:\\Users\\momad\\AppData\\Roaming\\Python\\Python36\\site-packages\\IPython\\core\\interactiveshell.py\", line 3343, in run_code\n",
      "    exec(code_obj, self.user_global_ns, self.user_ns)\n",
      "  File \"<ipython-input-2-1458a38dfacc>\", line 35, in <module>\n",
      "    model = design_model(features_train)\n",
      "  File \"<ipython-input-2-1458a38dfacc>\", line 18, in design_model\n",
      "    model.add(Dense(1))\n",
      "NameError: name 'Dense' is not defined\n",
      "\n",
      "During handling of the above exception, another exception occurred:\n",
      "\n",
      "Traceback (most recent call last):\n",
      "  File \"C:\\Users\\momad\\AppData\\Roaming\\Python\\Python36\\site-packages\\IPython\\core\\interactiveshell.py\", line 2044, in showtraceback\n",
      "    stb = value._render_traceback_()\n",
      "AttributeError: 'NameError' object has no attribute '_render_traceback_'\n",
      "\n",
      "During handling of the above exception, another exception occurred:\n",
      "\n",
      "Traceback (most recent call last):\n",
      "  File \"C:\\Users\\momad\\AppData\\Roaming\\Python\\Python36\\site-packages\\IPython\\core\\interactiveshell.py\", line 3263, in run_ast_nodes\n",
      "    if (await self.run_code(code, result,  async_=asy)):\n",
      "  File \"C:\\Users\\momad\\AppData\\Roaming\\Python\\Python36\\site-packages\\IPython\\core\\interactiveshell.py\", line 3360, in run_code\n",
      "    self.showtraceback(running_compiled_code=True)\n",
      "  File \"C:\\Users\\momad\\AppData\\Roaming\\Python\\Python36\\site-packages\\IPython\\core\\interactiveshell.py\", line 2047, in showtraceback\n",
      "    value, tb, tb_offset=tb_offset)\n",
      "  File \"C:\\Users\\momad\\AppData\\Roaming\\Python\\Python36\\site-packages\\IPython\\core\\ultratb.py\", line 1436, in structured_traceback\n",
      "    self, etype, value, tb, tb_offset, number_of_lines_of_context)\n",
      "  File \"C:\\Users\\momad\\AppData\\Roaming\\Python\\Python36\\site-packages\\IPython\\core\\ultratb.py\", line 1336, in structured_traceback\n",
      "    self, etype, value, tb, tb_offset, number_of_lines_of_context\n",
      "  File \"C:\\Users\\momad\\AppData\\Roaming\\Python\\Python36\\site-packages\\IPython\\core\\ultratb.py\", line 1193, in structured_traceback\n",
      "    tb_offset)\n",
      "  File \"C:\\Users\\momad\\AppData\\Roaming\\Python\\Python36\\site-packages\\IPython\\core\\ultratb.py\", line 1150, in format_exception_as_a_whole\n",
      "    last_unique, recursion_repeat = find_recursion(orig_etype, evalue, records)\n",
      "  File \"C:\\Users\\momad\\AppData\\Roaming\\Python\\Python36\\site-packages\\IPython\\core\\ultratb.py\", line 451, in find_recursion\n",
      "    return len(records), 0\n",
      "TypeError: object of type 'NoneType' has no len()\n",
      "\n",
      "During handling of the above exception, another exception occurred:\n",
      "\n",
      "Traceback (most recent call last):\n",
      "  File \"C:\\Users\\momad\\AppData\\Roaming\\Python\\Python36\\site-packages\\IPython\\core\\interactiveshell.py\", line 2044, in showtraceback\n",
      "    stb = value._render_traceback_()\n",
      "AttributeError: 'TypeError' object has no attribute '_render_traceback_'\n",
      "\n",
      "During handling of the above exception, another exception occurred:\n",
      "\n",
      "Traceback (most recent call last):\n",
      "  File \"C:\\Users\\momad\\AppData\\Roaming\\Python\\Python36\\site-packages\\IPython\\core\\ultratb.py\", line 1169, in get_records\n",
      "    return _fixed_getinnerframes(etb, number_of_lines_of_context, tb_offset)\n",
      "  File \"C:\\Users\\momad\\AppData\\Roaming\\Python\\Python36\\site-packages\\IPython\\core\\ultratb.py\", line 316, in wrapped\n",
      "    return f(*args, **kwargs)\n",
      "  File \"C:\\Users\\momad\\AppData\\Roaming\\Python\\Python36\\site-packages\\IPython\\core\\ultratb.py\", line 350, in _fixed_getinnerframes\n",
      "    records = fix_frame_records_filenames(inspect.getinnerframes(etb, context))\n",
      "  File \"C:\\Users\\momad\\anaconda3\\envs\\PythonData\\lib\\inspect.py\", line 1490, in getinnerframes\n",
      "    frameinfo = (tb.tb_frame,) + getframeinfo(tb, context)\n",
      "  File \"C:\\Users\\momad\\anaconda3\\envs\\PythonData\\lib\\inspect.py\", line 1448, in getframeinfo\n",
      "    filename = getsourcefile(frame) or getfile(frame)\n",
      "  File \"C:\\Users\\momad\\anaconda3\\envs\\PythonData\\lib\\inspect.py\", line 696, in getsourcefile\n",
      "    if getattr(getmodule(object, filename), '__loader__', None) is not None:\n",
      "  File \"C:\\Users\\momad\\anaconda3\\envs\\PythonData\\lib\\inspect.py\", line 733, in getmodule\n",
      "    if ismodule(module) and hasattr(module, '__file__'):\n",
      "  File \"C:\\Users\\momad\\anaconda3\\envs\\PythonData\\lib\\site-packages\\tensorflow\\__init__.py\", line 50, in __getattr__\n",
      "    module = self._load()\n",
      "  File \"C:\\Users\\momad\\anaconda3\\envs\\PythonData\\lib\\site-packages\\tensorflow\\__init__.py\", line 44, in _load\n",
      "    module = _importlib.import_module(self.__name__)\n",
      "  File \"C:\\Users\\momad\\anaconda3\\envs\\PythonData\\lib\\importlib\\__init__.py\", line 126, in import_module\n",
      "    return _bootstrap._gcd_import(name[level:], package, level)\n",
      "  File \"<frozen importlib._bootstrap>\", line 994, in _gcd_import\n",
      "  File \"<frozen importlib._bootstrap>\", line 971, in _find_and_load\n",
      "  File \"<frozen importlib._bootstrap>\", line 953, in _find_and_load_unlocked\n",
      "ModuleNotFoundError: No module named 'tensorflow_core.estimator'\n",
      "Traceback (most recent call last):\n",
      "  File \"C:\\Users\\momad\\AppData\\Roaming\\Python\\Python36\\site-packages\\IPython\\core\\interactiveshell.py\", line 3343, in run_code\n",
      "    exec(code_obj, self.user_global_ns, self.user_ns)\n",
      "  File \"<ipython-input-2-1458a38dfacc>\", line 35, in <module>\n",
      "    model = design_model(features_train)\n",
      "  File \"<ipython-input-2-1458a38dfacc>\", line 18, in design_model\n",
      "    model.add(Dense(1))\n",
      "NameError: name 'Dense' is not defined\n",
      "\n",
      "During handling of the above exception, another exception occurred:\n",
      "\n",
      "Traceback (most recent call last):\n",
      "  File \"C:\\Users\\momad\\AppData\\Roaming\\Python\\Python36\\site-packages\\IPython\\core\\interactiveshell.py\", line 2044, in showtraceback\n",
      "    stb = value._render_traceback_()\n",
      "AttributeError: 'NameError' object has no attribute '_render_traceback_'\n",
      "\n",
      "During handling of the above exception, another exception occurred:\n",
      "\n",
      "Traceback (most recent call last):\n",
      "  File \"C:\\Users\\momad\\AppData\\Roaming\\Python\\Python36\\site-packages\\IPython\\core\\interactiveshell.py\", line 3263, in run_ast_nodes\n",
      "    if (await self.run_code(code, result,  async_=asy)):\n",
      "  File \"C:\\Users\\momad\\AppData\\Roaming\\Python\\Python36\\site-packages\\IPython\\core\\interactiveshell.py\", line 3360, in run_code\n",
      "    self.showtraceback(running_compiled_code=True)\n",
      "  File \"C:\\Users\\momad\\AppData\\Roaming\\Python\\Python36\\site-packages\\IPython\\core\\interactiveshell.py\", line 2047, in showtraceback\n",
      "    value, tb, tb_offset=tb_offset)\n",
      "  File \"C:\\Users\\momad\\AppData\\Roaming\\Python\\Python36\\site-packages\\IPython\\core\\ultratb.py\", line 1436, in structured_traceback\n",
      "    self, etype, value, tb, tb_offset, number_of_lines_of_context)\n",
      "  File \"C:\\Users\\momad\\AppData\\Roaming\\Python\\Python36\\site-packages\\IPython\\core\\ultratb.py\", line 1336, in structured_traceback\n",
      "    self, etype, value, tb, tb_offset, number_of_lines_of_context\n",
      "  File \"C:\\Users\\momad\\AppData\\Roaming\\Python\\Python36\\site-packages\\IPython\\core\\ultratb.py\", line 1193, in structured_traceback\n",
      "    tb_offset)\n",
      "  File \"C:\\Users\\momad\\AppData\\Roaming\\Python\\Python36\\site-packages\\IPython\\core\\ultratb.py\", line 1150, in format_exception_as_a_whole\n",
      "    last_unique, recursion_repeat = find_recursion(orig_etype, evalue, records)\n",
      "  File \"C:\\Users\\momad\\AppData\\Roaming\\Python\\Python36\\site-packages\\IPython\\core\\ultratb.py\", line 451, in find_recursion\n",
      "    return len(records), 0\n",
      "TypeError: object of type 'NoneType' has no len()\n",
      "\n",
      "During handling of the above exception, another exception occurred:\n",
      "\n",
      "Traceback (most recent call last):\n",
      "  File \"C:\\Users\\momad\\AppData\\Roaming\\Python\\Python36\\site-packages\\IPython\\core\\interactiveshell.py\", line 2044, in showtraceback\n",
      "    stb = value._render_traceback_()\n",
      "AttributeError: 'TypeError' object has no attribute '_render_traceback_'\n",
      "\n",
      "During handling of the above exception, another exception occurred:\n",
      "\n",
      "Traceback (most recent call last):\n",
      "  File \"C:\\Users\\momad\\AppData\\Roaming\\Python\\Python36\\site-packages\\IPython\\core\\interactiveshell.py\", line 2895, in _run_cell\n",
      "    return runner(coro)\n",
      "  File \"C:\\Users\\momad\\AppData\\Roaming\\Python\\Python36\\site-packages\\IPython\\core\\async_helpers.py\", line 68, in _pseudo_sync_runner\n",
      "    coro.send(None)\n",
      "  File \"C:\\Users\\momad\\AppData\\Roaming\\Python\\Python36\\site-packages\\IPython\\core\\interactiveshell.py\", line 3072, in run_cell_async\n",
      "    interactivity=interactivity, compiler=compiler, result=result)\n",
      "  File \"C:\\Users\\momad\\AppData\\Roaming\\Python\\Python36\\site-packages\\IPython\\core\\interactiveshell.py\", line 3282, in run_ast_nodes\n",
      "    self.showtraceback()\n",
      "  File \"C:\\Users\\momad\\AppData\\Roaming\\Python\\Python36\\site-packages\\IPython\\core\\interactiveshell.py\", line 2047, in showtraceback\n",
      "    value, tb, tb_offset=tb_offset)\n",
      "  File \"C:\\Users\\momad\\AppData\\Roaming\\Python\\Python36\\site-packages\\IPython\\core\\ultratb.py\", line 1436, in structured_traceback\n",
      "    self, etype, value, tb, tb_offset, number_of_lines_of_context)\n",
      "  File \"C:\\Users\\momad\\AppData\\Roaming\\Python\\Python36\\site-packages\\IPython\\core\\ultratb.py\", line 1336, in structured_traceback\n",
      "    self, etype, value, tb, tb_offset, number_of_lines_of_context\n",
      "  File \"C:\\Users\\momad\\AppData\\Roaming\\Python\\Python36\\site-packages\\IPython\\core\\ultratb.py\", line 1211, in structured_traceback\n",
      "    chained_exceptions_tb_offset)\n",
      "  File \"C:\\Users\\momad\\AppData\\Roaming\\Python\\Python36\\site-packages\\IPython\\core\\ultratb.py\", line 1150, in format_exception_as_a_whole\n",
      "    last_unique, recursion_repeat = find_recursion(orig_etype, evalue, records)\n",
      "  File \"C:\\Users\\momad\\AppData\\Roaming\\Python\\Python36\\site-packages\\IPython\\core\\ultratb.py\", line 451, in find_recursion\n",
      "    return len(records), 0\n",
      "TypeError: object of type 'NoneType' has no len()\n",
      "\n",
      "During handling of the above exception, another exception occurred:\n",
      "\n",
      "Traceback (most recent call last):\n",
      "  File \"C:\\Users\\momad\\AppData\\Roaming\\Python\\Python36\\site-packages\\IPython\\core\\interactiveshell.py\", line 2044, in showtraceback\n",
      "    stb = value._render_traceback_()\n",
      "AttributeError: 'TypeError' object has no attribute '_render_traceback_'\n",
      "\n",
      "During handling of the above exception, another exception occurred:\n",
      "\n",
      "Traceback (most recent call last):\n",
      "  File \"C:\\Users\\momad\\AppData\\Roaming\\Python\\Python36\\site-packages\\IPython\\core\\ultratb.py\", line 1169, in get_records\n",
      "    return _fixed_getinnerframes(etb, number_of_lines_of_context, tb_offset)\n",
      "  File \"C:\\Users\\momad\\AppData\\Roaming\\Python\\Python36\\site-packages\\IPython\\core\\ultratb.py\", line 316, in wrapped\n",
      "    return f(*args, **kwargs)\n",
      "  File \"C:\\Users\\momad\\AppData\\Roaming\\Python\\Python36\\site-packages\\IPython\\core\\ultratb.py\", line 350, in _fixed_getinnerframes\n",
      "    records = fix_frame_records_filenames(inspect.getinnerframes(etb, context))\n",
      "  File \"C:\\Users\\momad\\anaconda3\\envs\\PythonData\\lib\\inspect.py\", line 1490, in getinnerframes\n",
      "    frameinfo = (tb.tb_frame,) + getframeinfo(tb, context)\n",
      "  File \"C:\\Users\\momad\\anaconda3\\envs\\PythonData\\lib\\inspect.py\", line 1448, in getframeinfo\n",
      "    filename = getsourcefile(frame) or getfile(frame)\n",
      "  File \"C:\\Users\\momad\\anaconda3\\envs\\PythonData\\lib\\inspect.py\", line 696, in getsourcefile\n",
      "    if getattr(getmodule(object, filename), '__loader__', None) is not None:\n",
      "  File \"C:\\Users\\momad\\anaconda3\\envs\\PythonData\\lib\\inspect.py\", line 733, in getmodule\n",
      "    if ismodule(module) and hasattr(module, '__file__'):\n",
      "  File \"C:\\Users\\momad\\anaconda3\\envs\\PythonData\\lib\\site-packages\\tensorflow\\__init__.py\", line 50, in __getattr__\n",
      "    module = self._load()\n",
      "  File \"C:\\Users\\momad\\anaconda3\\envs\\PythonData\\lib\\site-packages\\tensorflow\\__init__.py\", line 44, in _load\n",
      "    module = _importlib.import_module(self.__name__)\n",
      "  File \"C:\\Users\\momad\\anaconda3\\envs\\PythonData\\lib\\importlib\\__init__.py\", line 126, in import_module\n",
      "    return _bootstrap._gcd_import(name[level:], package, level)\n",
      "  File \"<frozen importlib._bootstrap>\", line 994, in _gcd_import\n",
      "  File \"<frozen importlib._bootstrap>\", line 971, in _find_and_load\n",
      "  File \"<frozen importlib._bootstrap>\", line 953, in _find_and_load_unlocked\n",
      "ModuleNotFoundError: No module named 'tensorflow_core.estimator'\n"
     ]
    }
   ],
   "source": [
    "import pandas as pd\n",
    "import tensorflow as tf\n",
    "from sklearn.model_selection import train_test_split\n",
    "from sklearn.compose import ColumnTransformer\n",
    "from sklearn.preprocessing import StandardScaler\n",
    "from tensorflow.keras.models import Sequential\n",
    "from tensorflow.keras import layers\n",
    "\n",
    "\n",
    "def design_model(features):\n",
    "  model = Sequential(name = \"my_first_model\")\n",
    "  #get the number of features/dimensions in the data\n",
    "  num_features = features.shape[1] \n",
    "  #without hard-coding\n",
    "  input = layers.InputLayer(input_shape=(num_features,)) \n",
    "  #adding the input layer\n",
    "  model.add(input) \n",
    "  model.add(Dense(1))\n",
    "  return model\n",
    "\n",
    "\n",
    "dataset = pd.read_csv('insurance.csv') #load the dataset\n",
    "features = dataset.iloc[:,0:6] #choose first 7 columns as features\n",
    "labels = dataset.iloc[:,-1] #choose the final column for prediction\n",
    "\n",
    "features = pd.get_dummies(features) #one-hot encoding for categorical variables\n",
    "features_train, features_test, labels_train, labels_test = train_test_split(features, labels, test_size=0.33, random_state=42) #split the data into training and test data\n",
    " \n",
    "#standardize\n",
    "ct = ColumnTransformer([('standardize', StandardScaler(), ['age', 'bmi', 'children'])], remainder='passthrough')\n",
    "features_train = ct.fit_transform(features_train)\n",
    "features_test = ct.transform(features_test)\n",
    "\n",
    "#invoke the function for our model design\n",
    "model = design_model(features_train)\n",
    "print(model.summary())"
   ]
  },
  {
   "cell_type": "code",
   "execution_count": null,
   "metadata": {},
   "outputs": [],
   "source": []
  }
 ],
 "metadata": {
  "kernelspec": {
   "display_name": "Python 3",
   "language": "python",
   "name": "python3"
  },
  "language_info": {
   "codemirror_mode": {
    "name": "ipython",
    "version": 3
   },
   "file_extension": ".py",
   "mimetype": "text/x-python",
   "name": "python",
   "nbconvert_exporter": "python",
   "pygments_lexer": "ipython3",
   "version": "3.6.10"
  }
 },
 "nbformat": 4,
 "nbformat_minor": 4
}
